<?xml version="1.0"?>
<robot xmlns:xacro="http://www.ros.org/wiki/xacro" >
    
    <xacro:include filename="inertial_macros.xacro" />
    <material name="white">
        <color rgba="1 1 1 1" />
    </material>

    <material name="orange">
        <color rgba="1 0.3 0.1 1"/>
    </material>

    <material name="blue">
        <color rgba="0.2 0.2 1 1"/>
    </material>

    <material name="black">
        <color rgba="0 0 0 1"/>
    </material>

    <material name="red">
        <color rgba="1 0 0 1"/>
    </material>

    <!-- BASE LINK -->

    <link name="base_link">

    </link>
    <joint name="base_footprint_joint" type="fixed">
        <parent link="base_link"/>
        <child link="base_footprint"/>
        <origin xyz="0 0 0" rpy="0 0 0"/>
    </joint>

    <link name="base_footprint">
    </link>

    <joint name="chassis_joint" type="fixed">
        <parent link="base_link"/>
        <child link="chassis"/>
    <origin xyz="-0.1 0 0"/>
    </joint>
    
    <link name="chassis">
        <visual>
            <origin xyz="0.15 0 0.075" rpy="0 0 0"/>
            <geometry>
                <box size="0.3 0.3 0.15"/>
            </geometry>
            <material name="white"/>
        </visual>
        <collision>
            <origin xyz="0.15 0 0.075" rpy="0 0 0"/>
            <geometry>
                <box size="0.3 0.3 0.15"/>
        </geometry>
        </collision>
        <xacro:inertial_box mass="0.5" x="0.3" y="0.3" z="0.15">
            <origin xyz="0.15 0 0.075" rpy="0 0 0"/>
        </xacro:inertial_box>
    </link>
    <gazebo reference="chassis">
        <material>Gazebo/White</material>
    </gazebo>


    <!-- LEFT WHEEL -->

    <joint name="left_wheel_joint" type="continuous">
        <parent link="base_link"/>
        <child link="left_wheel"/>
        <origin xyz="0 0.175 0" rpy="-${pi/2} 0 0"/>
        <axis xyz="0 0 1"/>
    </joint>
    <link name="left_wheel">
        <visual>
            <geometry>
                <cylinder length="0.04" radius="0.05" />
            </geometry>
            <material name="blue"/>
        </visual>
        <collision>
            <geometry>
                <cylinder length="0.04" radius="0.05" />
            </geometry>
        </collision>
        <xacro:inertial_cylinder mass="0.1" length="0.04" radius="0.05">
            <origin xyz="0 0 0" rpy="0 0 0"/>
        </xacro:inertial_cylinder>
    </link>
    <gazebo reference="left_wheel">
        <material>Gazebo/Blue</material>
    </gazebo>

    <!-- LEFT WHEEL -->
    <!-- LEFT WHEEL2 -->
    <joint name="left_wheel_joint2" type="fixed">
        <parent link="base_link"/>
        <child link="left_wheel2"/>
        <origin xyz="0.15 0.175 0" rpy="-${pi/2} 0 0"/>
        <axis xyz="0 0 1"/>
    </joint>
    <link name="left_wheel2">
        <visual>
            <geometry>
                <cylinder length="0.04" radius="0.05" />
            </geometry>
            <material name="blue"/>
        </visual>
    </link>
    <gazebo reference="left_wheel2">
        <material>Gazebo/Blue</material>
    </gazebo>
    
    <!-- LEFT WHEEL2 -->



    <!-- RIGHT WHEEL -->

    <joint name="right_wheel_joint" type="continuous">
        <parent link="base_link"/>
        <child link="right_wheel"/>
        <origin xyz="0 -0.175 0" rpy="${pi/2} 0 0"/>
        <axis xyz="0 0 -1"/>
    </joint>

    <link name="right_wheel">
        <visual>
            <geometry>
                <cylinder length="0.04" radius="0.05" />
            </geometry>
            <material name="blue"/>
        </visual>
        <collision>
            <geometry>
                <cylinder length="0.04" radius="0.05" />
            </geometry>
        </collision>
        <xacro:inertial_sphere mass="0.1" radius="0.05">
            <origin xyz="0 0 0" rpy="0 0 0"/>
        </xacro:inertial_sphere>
    </link>
    <gazebo reference="right_wheel">
        <material>Gazebo/Blue</material>
    </gazebo>
    <!-- RIGHT WHEEL -->
    <!-- RIGHT WHEEL2 -->
    <joint name="right_wheel_joint2" type="fixed">
        <parent link="base_link"/>
        <child link="right_wheel2"/>
        <origin xyz="0.15 -0.175 0" rpy="${pi/2} 0 0"/>
        <axis xyz="0 0 -1"/>
    </joint>

    <link name="right_wheel2">
        <visual>
            <geometry>
                <cylinder length="0.04" radius="0.05" />
            </geometry>
            <material name="blue"/>
        </visual>
    </link>
    <gazebo reference="right_wheel2">
        <material>Gazebo/Blue</material>
    </gazebo>
    
    <!-- RIGHT WHEEL2 -->
    

    
    
    


    <!-- CASTER WHEEL -->

    <joint name="caster_wheel_joint" type="fixed">
        <parent link="chassis"/>
        <child link="caster_wheel"/>
        <origin xyz="0.24 0 0" rpy="0 0 0"/>
    </joint>

    <link name="caster_wheel">
        <visual>
            <geometry>
                <sphere radius="0.05" />
            </geometry>
            <material name="black"/>
        </visual>
        <collision>
            <geometry>
                <sphere radius="0.05" />
            </geometry>
        </collision>
        <xacro:inertial_sphere mass="0.1" radius="0.05">
            <origin xyz="0 0 0" rpy="0 0 0"/>
        </xacro:inertial_sphere>
    </link>
    <gazebo reference="caster_wheel">
        <material>Gazebo/Black</material>
        <mu1 value="0.001"/>
        <mu2 value="0.001"/>
    </gazebo>
    

    <!--  WHEEL -->

    <joint name="wheel_joint" type="fixed">
        <parent link="base_link"/>
        <child link="wheel"/>
        <origin xyz="0.175 -0.1 0.175" rpy="0 0 0"/>
        <axis xyz="0 0 0"/>
    </joint>

    <link name="wheel">
        <visual>
            <geometry>
                <cylinder length="0.04" radius="0.05" />
            </geometry>
            <material name="red"/>
        </visual>
        <collision>
            <geometry>
                <cylinder length="0.04" radius="0.05" />
            </geometry>
        </collision>
        <xacro:inertial_sphere mass="0.1" radius="0.05">
            <origin xyz="0 0 0" rpy="0 0 0"/>
        </xacro:inertial_sphere>
    </link>
    <gazebo reference="wheel">
        <material>Gazebo/Red</material>
    </gazebo>
   
    <!--  แขน -->

    <joint name="arm_joint" type="revolute">
        <parent link="wheel"/>
        <child link="arm1"/>
        <axis xyz="0 0 1"/>
        <origin xyz="0 0 -0.08"/>
        
        <limit lower="-1" upper="0" velocity="100" effort="100"/> 
    </joint>

    <link name="arm1">
        <visual>
            <origin xyz="0.125 0 0" rpy="0 0 0"/>
            <geometry>
                <box size="0.15 0.02 0.2"/>
            </geometry>
            <material name="blue"/>
        </visual>
        <xacro:inertial_sphere mass="0.1" radius="0.05">
            <origin xyz="0 0 0" rpy="0 0 0"/>
        </xacro:inertial_sphere>
    </link>
    <gazebo reference="arm1">
        <material>Gazebo/Blue</material>
    </gazebo>


    <!--  wheel2 -->

    <joint name="wheel_joint2" type="fixed">
        <parent link="base_link"/>
        <child link="wheel2"/>
        <origin xyz="0.175 0.1 0.175" rpy="0 0 0"/>
        <axis xyz="0 0 0"/>
    </joint>

    <link name="wheel2">
        <visual>
            <geometry>
                <cylinder length="0.04" radius="0.05" />
            </geometry>
            <material name="red"/>
        </visual>
        <collision>
            <geometry>
                <cylinder length="0.04" radius="0.05" />
            </geometry>
        </collision>
        <xacro:inertial_sphere mass="0.1" radius="0.05">
            <origin xyz="0 0 0" rpy="0 0 0"/>
        </xacro:inertial_sphere>
    </link>
    <gazebo reference="wheel2">
        <material>Gazebo/Red</material>
    </gazebo>

    <!--  แขน2 -->

    <joint name="arm_joint2" type="revolute">
        <parent link="wheel2"/>
        <child link="arm2"/>
        <axis xyz="0 0 1"/>
        <origin xyz="0 0 -0.08"/>
        
        <limit lower="1" upper="0" velocity="100" effort="100"/> 
    </joint>

    <link name="arm2">
        <visual>
            <origin xyz="0.125 0 0" rpy="0 0 0"/>
            <geometry>
                <box size="0.15 0.02 0.2"/>
            </geometry>
            <material name="blue"/>
        </visual>
        <xacro:inertial_sphere mass="0.1" radius="0.05">
            <origin xyz="0 0 0" rpy="0 0 0"/>
        </xacro:inertial_sphere>
    </link>
    <gazebo reference="arm2">
        <material>Gazebo/Blue</material>
    </gazebo>


    <!--  partแขน1 -->

    <joint name="part_arm_joint" type="fixed">
        <parent link="arm1"/>
        <child link="part_arm"/>
        <axis xyz="0 0 1"/>
        <origin xyz="0.075 0.04 0"/>
        
        <limit lower="-1" upper="0" velocity="100" effort="100"/> 
    </joint>

    <link name="part_arm">
        <visual>
            <origin xyz="0.125 0 0" rpy="0 0 0"/>
            <geometry>
                <box size="0.01 0.1 0.2"/>
            </geometry>
            <material name="orange"/>
        </visual>
    </link>
    <gazebo reference="part_arm">
        <material>Gazebo/Blue</material>
    </gazebo>
    

    <!--  partแขน1 -->


    <joint name="part_arm_joint2" type="fixed">
        <parent link="arm2"/>
        <child link="part_arm2"/>
        <axis xyz="0 0 1"/>
        <origin xyz="0.075 -0.04 0"/>
        
        <limit lower="-1" upper="0" velocity="100" effort="100"/> 
    </joint>

    <link name="part_arm2">
        <visual>
            <origin xyz="0.125 0 0" rpy="0 0 0"/>
            <geometry>
                <box size="0.01 0.1 0.2"/>
            </geometry>
            <material name="orange"/>
        </visual>
    </link>
    <gazebo reference="part_arm2">
        <material>Gazebo/Blue</material>
    </gazebo>
    


   
</robot>